"""
Домашнее задание №13: Обработка исключений. Собственные 
исключения.

Функция plus_two() выполняет одну простую задачу — выводит результат сложения переданного в нее числа 2 и значения переменной number. В переменную number должно быть передано число. Обработайте ситуацию, если в эту переменную переданы данные какого-то другого типа. В случае ошибки напечатайте в консоли сообщение «Ожидаемый тип данных — число!».
Используйте конструкцию try/except.В процессе поиска решения попробуйте вывести в консоль сумму строки и числа, изучите сообщение об ошибке.В Python есть специальное исключение для ситуации, если тип переданного значения не соответствует ожиданиям. 
"""

def plus_two(number):
    try:
        result = number + 2
        print(f"Результата: {result}")
    except TypeError:
        print("Ожидаемый тип данных — число!")

# Пример использования
plus_two(1) # результат 3
plus_two("text")  # Ожидаемый тип данных — число!
